Workbook

Sheet Instructions
A1: Teacher Configuration — CSE Dept, Varendra University
A3: Purpose: single source of truth for teacher credit limits and theory-course quotas, used by the automated assignment engine each semester.
A5: How to use:
A6: 1. Go to the "Teachers" tab. One row per teacher.
A7: 2. "Designation" is a dropdown — pick from Head / Coordinator / Associate Professor / Assistant Professor / Professor / Lecturer.
A8: 3. "Default Credit Limit" and "Default Theory Target" fill in automatically based on Designation (see "Designation Defaults" tab).
A9: 4. Only fill "Credit Limit Override" or "Theory Target Override" (yellow cells) if this specific teacher differs from the default — e.g. a course-load waiver for extra departmental duties. Leave blank otherwise.
A10: 5. "Final Credit Limit" / "Final Theory Target" (used by the engine) = Override if given, else Default. Do not edit these — they are formulas.
A11: 6. Add new teachers as new rows at the bottom; keep SL No sequential.
A12: 7. To change a default for an entire designation (e.g. all Lecturers move from 18 to 17 credits), edit it once on the "Designation Defaults" tab — every teacher with that designation updates automatically.
A14: Rows highlighted in red on the Teachers tab are teachers found in the course-choice submissions with NO Initial or credit data yet on file — fill in their Initial and check/set their credit limit before running the assignment engine.

Sheet Designation Defaults
A1: Designation | B1: Default Credit Limit | C1: Default Theory Target
A2: Head | B2: 6 | C2: 1
A3: Coordinator | B3: 9 | C3: 2
A4: Associate Professor | B4: 12 | C4: 2
A5: Assistant Professor | B5: 15 | C5: 3
A6: Professor | B6: 12 | C6: 2
A7: Lecturer | B7: 18 | C7: 3
A9: Blue/yellow cells are editable defaults. Changing one here updates every teacher with that designation on the Teachers tab.

Sheet Teachers
A1: SL No | B1: Name | C1: Initial | D1: Designation | E1: Default Credit Limit | F1: Credit Limit Override | G1: Final Credit Limit | H1: Default Theory Target | I1: Theory Target Override | J1: Final Theory Target | K1: Notes / Waiver Reason
A2: 1 | B2: Prof. Shamim Ahmad | C2: SA | D2: Head | E2: =IFERROR(INDEX('Designation Defaults'!$B$2:$B$7,MATCH(D2,'Designation Defaults'!$A$2:$A$7,0)),"") -> 6 | G2: =IF(F2="",E2,F2) -> 6 | H2: =IFERROR(INDEX('Designation Defaults'!$C$2:$C$7,MATCH(D2,'Designation Defaults'!$A$2:$A$7,0)),"") -> 1 | J2: =IF(I2="",H2,I2) -> 1
A3: 2 | B3: Dr. Ahammad Hossain | C3: AH | D3: Associate Professor | E3: =IFERROR(INDEX('Designation Defaults'!$B$2:$B$7,MATCH(D3,'Designation Defaults'!$A$2:$A$7,0)),"") -> 12 | F3: 15 | G3: =IF(F3="",E3,F3) -> 15 | H3: =IFERROR(INDEX('Designation Defaults'!$C$2:$C$7,MATCH(D3,'Designation Defaults'!$A$2:$A$7,0)),"") -> 2 | J3: =IF(I3="",H3,I3) -> 2
A4: 3 | B4: Md. Mizanur Rahman | C4: MR | D4: Assistant Professor | E4: =IFERROR(INDEX('Designation Defaults'!$B$2:$B$7,MATCH(D4,'Designation Defaults'!$A$2:$A$7,0)),"") -> 15 | F4: 18 | G4: =IF(F4="",E4,F4) -> 18 | H4: =IFERROR(INDEX('Designation Defaults'!$C$2:$C$7,MATCH(D4,'Designation Defaults'!$A$2:$A$7,0)),"") -> 3 | J4: =IF(I4="",H4,I4) -> 3
A5: 4 | B5: Umme Rumman | C5: URC | D5: Assistant Professor | E5: =IFERROR(INDEX('Designation Defaults'!$B$2:$B$7,MATCH(D5,'Designation Defaults'!$A$2:$A$7,0)),"") -> 15 | F5: 18 | G5: =IF(F5="",E5,F5) -> 18 | H5: =IFERROR(INDEX('Designation Defaults'!$C$2:$C$7,MATCH(D5,'Designation Defaults'!$A$2:$A$7,0)),"") -> 3 | J5: =IF(I5="",H5,I5) -> 3
A6: 5 | B6: Mst. Jannatul Ferdous | C6: JF | D6: Assistant Professor | E6: =IFERROR(INDEX('Designation Defaults'!$B$2:$B$7,MATCH(D6,'Designation Defaults'!$A$2:$A$7,0)),"") -> 15 | F6: 18 | G6: =IF(F6="",E6,F6) -> 18 | H6: =IFERROR(INDEX('Designation Defaults'!$C$2:$C$7,MATCH(D6,'Designation Defaults'!$A$2:$A$7,0)),"") -> 3 | J6: =IF(I6="",H6,I6) -> 3
A7: 6 | B7: Sumaia Rahman | C7: SR | D7: Assistant Professor | E7: =IFERROR(INDEX('Designation Defaults'!$B$2:$B$7,MATCH(D7,'Designation Defaults'!$A$2:$A$7,0)),"") -> 15 | F7: 18 | G7: =IF(F7="",E7,F7) -> 18 | H7: =IFERROR(INDEX('Designation Defaults'!$C$2:$C$7,MATCH(D7,'Designation Defaults'!$A$2:$A$7,0)),"") -> 3 | J7: =IF(I7="",H7,I7) -> 3
A8: 7 | B8: Tanver Ahmed | D8: Assistant Professor | E8: =IFERROR(INDEX('Designation Defaults'!$B$2:$B$7,MATCH(D8,'Designation Defaults'!$A$2:$A$7,0)),"") -> 15 | G8: =IF(F8="",E8,F8) -> 15 | H8: =IFERROR(INDEX('Designation Defaults'!$C$2:$C$7,MATCH(D8,'Designation Defaults'!$A$2:$A$7,0)),"") -> 3 | J8: =IF(I8="",H8,I8) -> 3 | K8: NEEDS SETUP: no Initial / credit limit on file — fill in before running engine
A9: 8 | B9: A.S.M. Delwar Hossain | C9: DH | D9: Lecturer | E9: =IFERROR(INDEX('Designation Defaults'!$B$2:$B$7,MATCH(D9,'Designation Defaults'!$A$2:$A$7,0)),"") -> 18 | G9: =IF(F9="",E9,F9) -> 18 | H9: =IFERROR(INDEX('Designation Defaults'!$C$2:$C$7,MATCH(D9,'Designation Defaults'!$A$2:$A$7,0)),"") -> 3 | J9: =IF(I9="",H9,I9) -> 3
A10: 9 | B10: Md. Toufikul Islam | C10: MTI | D10: Lecturer | E10: =IFERROR(INDEX('Designation Defaults'!$B$2:$B$7,MATCH(D10,'Designation Defaults'!$A$2:$A$7,0)),"") -> 18 | G10: =IF(F10="",E10,F10) -> 18 | H10: =IFERROR(INDEX('Designation Defaults'!$C$2:$C$7,MATCH(D10,'Designation Defaults'!$A$2:$A$7,0)),"") -> 3 | J10: =IF(I10="",H10,I10) -> 3
A11: 10 | B11: Md. Nour Noby | C11: NN | D11: Lecturer | E11: =IFERROR(INDEX('Designation Defaults'!$B$2:$B$7,MATCH(D11,'Designation Defaults'!$A$2:$A$7,0)),"") -> 18 | G11: =IF(F11="",E11,F11) -> 18 | H11: =IFERROR(INDEX('Designation Defaults'!$C$2:$C$7,MATCH(D11,'Designation Defaults'!$A$2:$A$7,0)),"") -> 3 | J11: =IF(I11="",H11,I11) -> 3
A12: 11 | B12: Ayesha Akter Lima | C12: AAL | D12: Lecturer | E12: =IFERROR(INDEX('Designation Defaults'!$B$2:$B$7,MATCH(D12,'Designation Defaults'!$A$2:$A$7,0)),"") -> 18 | G12: =IF(F12="",E12,F12) -> 18 | H12: =IFERROR(INDEX('Designation Defaults'!$C$2:$C$7,MATCH(D12,'Designation Defaults'!$A$2:$A$7,0)),"") -> 3 | J12: =IF(I12="",H12,I12) -> 3
A13: 12 | B13: Salma Akter Lima | C13: SAL | D13: Lecturer | E13: =IFERROR(INDEX('Designation Defaults'!$B$2:$B$7,MATCH(D13,'Designation Defaults'!$A$2:$A$7,0)),"") -> 18 | G13: =IF(F13="",E13,F13) -> 18 | H13: =IFERROR(INDEX('Designation Defaults'!$C$2:$C$7,MATCH(D13,'Designation Defaults'!$A$2:$A$7,0)),"") -> 3 | J13: =IF(I13="",H13,I13) -> 3
A14: 13 | B14: Ipshita Tasnim Raha | C14: ITR | D14: Lecturer | E14: =IFERROR(INDEX('Designation Defaults'!$B$2:$B$7,MATCH(D14,'Designation Defaults'!$A$2:$A$7,0)),"") -> 18 | G14: =IF(F14="",E14,F14) -> 18 | H14: =IFERROR(INDEX('Designation Defaults'!$C$2:$C$7,MATCH(D14,'Designation Defaults'!$A$2:$A$7,0)),"") -> 3 | J14: =IF(I14="",H14,I14) -> 3
A15: 14 | B15: Sumaiya Tasnim | C15: ST | D15: Lecturer | E15: =IFERROR(INDEX('Designation Defaults'!$B$2:$B$7,MATCH(D15,'Designation Defaults'!$A$2:$A$7,0)),"") -> 18 | G15: =IF(F15="",E15,F15) -> 18 | H15: =IFERROR(INDEX('Designation Defaults'!$C$2:$C$7,MATCH(D15,'Designation Defaults'!$A$2:$A$7,0)),"") -> 3 | J15: =IF(I15="",H15,I15) -> 3
A16: 15 | B16: Shamim Reza | C16: SHR | D16: Lecturer | E16: =IFERROR(INDEX('Designation Defaults'!$B$2:$B$7,MATCH(D16,'Designation Defaults'!$A$2:$A$7,0)),"") -> 18 | G16: =IF(F16="",E16,F16) -> 18 | H16: =IFERROR(INDEX('Designation Defaults'!$C$2:$C$7,MATCH(D16,'Designation Defaults'!$A$2:$A$7,0)),"") -> 3 | J16: =IF(I16="",H16,I16) -> 3
A17: 16 | B17: Samira Tareque | C17: SMT | D17: Lecturer | E17: =IFERROR(INDEX('Designation Defaults'!$B$2:$B$7,MATCH(D17,'Designation Defaults'!$A$2:$A$7,0)),"") -> 18 | G17: =IF(F17="",E17,F17) -> 18 | H17: =IFERROR(INDEX('Designation Defaults'!$C$2:$C$7,MATCH(D17,'Designation Defaults'!$A$2:$A$7,0)),"") -> 3 | J17: =IF(I17="",H17,I17) -> 3
A18: 17 | B18: Akib ikbal | C18: AKI | D18: Lecturer | E18: =IFERROR(INDEX('Designation Defaults'!$B$2:$B$7,MATCH(D18,'Designation Defaults'!$A$2:$A$7,0)),"") -> 18 | G18: =IF(F18="",E18,F18) -> 18 | H18: =IFERROR(INDEX('Designation Defaults'!$C$2:$C$7,MATCH(D18,'Designation Defaults'!$A$2:$A$7,0)),"") -> 3 | J18: =IF(I18="",H18,I18) -> 3
A19: 18 | B19: Mohammad Faisal Al-Naser | C19: MFA | D19: Lecturer | E19: =IFERROR(INDEX('Designation Defaults'!$B$2:$B$7,MATCH(D19,'Designation Defaults'!$A$2:$A$7,0)),"") -> 18 | G19: =IF(F19="",E19,F19) -> 18 | H19: =IFERROR(INDEX('Designation Defaults'!$C$2:$C$7,MATCH(D19,'Designation Defaults'!$A$2:$A$7,0)),"") -> 3 | J19: =IF(I19="",H19,I19) -> 3
A20: 19 | B20: Ahmed-Al-Azmain | C20: AAA | D20: Lecturer | E20: =IFERROR(INDEX('Designation Defaults'!$B$2:$B$7,MATCH(D20,'Designation Defaults'!$A$2:$A$7,0)),"") -> 18 | G20: =IF(F20="",E20,F20) -> 18 | H20: =IFERROR(INDEX('Designation Defaults'!$C$2:$C$7,MATCH(D20,'Designation Defaults'!$A$2:$A$7,0)),"") -> 3 | J20: =IF(I20="",H20,I20) -> 3
... A25: 24 | B25: Zannatul Mifta | C25: ZM | D25: Lecturer | E25: =IFERROR(INDEX('Designation Defaults'!$B$2:$B$7,MATCH(D25,'Designation Defaults'!$A$2:$A$7,0)),"") -> 18 | G25: =IF(F25="",E25,F25) -> 18 | H25: =IFERROR(INDEX('Designation Defaults'!$C$2:$C$7,MATCH(D25,'Designation Defaults'!$A$2:$A$7,0)),"") -> 3 | J25: =IF(I25="",H25,I25) -> 3
A26: 25 | B26: Arun Kumar Sikder | D26: Lecturer | E26: =IFERROR(INDEX('Designation Defaults'!$B$2:$B$7,MATCH(D26,'Designation Defaults'!$A$2:$A$7,0)),"") -> 18 | G26: =IF(F26="",E26,F26) -> 18 | H26: =IFERROR(INDEX('Designation Defaults'!$C$2:$C$7,MATCH(D26,'Designation Defaults'!$A$2:$A$7,0)),"") -> 3 | J26: =IF(I26="",H26,I26) -> 3 | K26: NEEDS SETUP: no Initial / credit limit on file — fill in before running engine
A27: 26 | B27: Sushmit Jahan | C27: SJR | D27: Lecturer | E27: =IFERROR(INDEX('Designation Defaults'!$B$2:$B$7,MATCH(D27,'Designation Defaults'!$A$2:$A$7,0)),"") -> 18 | G27: =IF(F27="",E27,F27) -> 18 | H27: =IFERROR(INDEX('Designation Defaults'!$C$2:$C$7,MATCH(D27,'Designation Defaults'!$A$2:$A$7,0)),"") -> 3 | J27: =IF(I27="",H27,I27) -> 3
A28: 27 | B28: Md. Ruhul Amin | C28: RA | D28: Lecturer | E28: =IFERROR(INDEX('Designation Defaults'!$B$2:$B$7,MATCH(D28,'Designation Defaults'!$A$2:$A$7,0)),"") -> 18 | G28: =IF(F28="",E28,F28) -> 18 | H28: =IFERROR(INDEX('Designation Defaults'!$C$2:$C$7,MATCH(D28,'Designation Defaults'!$A$2:$A$7,0)),"") -> 3 | J28: =IF(I28="",H28,I28) -> 3
A29: 28 | B29: Md. Mahfujur Rahman | C29: MMR | D29: Lecturer | E29: =IFERROR(INDEX('Designation Defaults'!$B$2:$B$7,MATCH(D29,'Designation Defaults'!$A$2:$A$7,0)),"") -> 18 | G29: =IF(F29="",E29,F29) -> 18 | H29: =IFERROR(INDEX('Designation Defaults'!$C$2:$C$7,MATCH(D29,'Designation Defaults'!$A$2:$A$7,0)),"") -> 3 | J29: =IF(I29="",H29,I29) -> 3
A30: 29 | B30: D.M. Asadujjaman | C30: DMA | D30: Lecturer | E30: =IFERROR(INDEX('Designation Defaults'!$B$2:$B$7,MATCH(D30,'Designation Defaults'!$A$2:$A$7,0)),"") -> 18 | G30: =IF(F30="",E30,F30) -> 18 | H30: =IFERROR(INDEX('Designation Defaults'!$C$2:$C$7,MATCH(D30,'Designation Defaults'!$A$2:$A$7,0)),"") -> 3 | J30: =IF(I30="",H30,I30) -> 3
A31: 30 | B31: Israt Jahan Rinky | C31: IJR | D31: Lecturer | E31: =IFERROR(INDEX('Designation Defaults'!$B$2:$B$7,MATCH(D31,'Designation Defaults'!$A$2:$A$7,0)),"") -> 18 | G31: =IF(F31="",E31,F31) -> 18 | H31: =IFERROR(INDEX('Designation Defaults'!$C$2:$C$7,MATCH(D31,'Designation Defaults'!$A$2:$A$7,0)),"") -> 3 | J31: =IF(I31="",H31,I31) -> 3
A32: 31 | B32: Protik Chakroborty | C32: PRC | D32: Lecturer | E32: =IFERROR(INDEX('Designation Defaults'!$B$2:$B$7,MATCH(D32,'Designation Defaults'!$A$2:$A$7,0)),"") -> 18 | G32: =IF(F32="",E32,F32) -> 18 | H32: =IFERROR(INDEX('Designation Defaults'!$C$2:$C$7,MATCH(D32,'Designation Defaults'!$A$2:$A$7,0)),"") -> 3 | J32: =IF(I32="",H32,I32) -> 3
A33: 32 | B33: Shorav Paul | C33: SP | D33: Lecturer | E33: =IFERROR(INDEX('Designation Defaults'!$B$2:$B$7,MATCH(D33,'Designation Defaults'!$A$2:$A$7,0)),"") -> 18 | G33: =IF(F33="",E33,F33) -> 18 | H33: =IFERROR(INDEX('Designation Defaults'!$C$2:$C$7,MATCH(D33,'Designation Defaults'!$A$2:$A$7,0)),"") -> 3 | J33: =IF(I33="",H33,I33) -> 3
A34: 33 | B34: Arshad Wasif | C34: AW | D34: Lecturer | E34: =IFERROR(INDEX('Designation Defaults'!$B$2:$B$7,MATCH(D34,'Designation Defaults'!$A$2:$A$7,0)),"") -> 18 | G34: =IF(F34="",E34,F34) -> 18 | H34: =IFERROR(INDEX('Designation Defaults'!$C$2:$C$7,MATCH(D34,'Designation Defaults'!$A$2:$A$7,0)),"") -> 3 | J34: =IF(I34="",H34,I34) -> 3
A35: 34 | B35: Md. Taufiq Khan | C35: MTK | D35: Lecturer | E35: =IFERROR(INDEX('Designation Defaults'!$B$2:$B$7,MATCH(D35,'Designation Defaults'!$A$2:$A$7,0)),"") -> 18 | G35: =IF(F35="",E35,F35) -> 18 | H35: =IFERROR(INDEX('Designation Defaults'!$C$2:$C$7,MATCH(D35,'Designation Defaults'!$A$2:$A$7,0)),"") -> 3 | J35: =IF(I35="",H35,I35) -> 3
A36: 35 | B36: Mst. Nafia Islam Shishir | D36: Lecturer | E36: =IFERROR(INDEX('Designation Defaults'!$B$2:$B$7,MATCH(D36,'Designation Defaults'!$A$2:$A$7,0)),"") -> 18 | G36: =IF(F36="",E36,F36) -> 18 | H36: =IFERROR(INDEX('Designation Defaults'!$C$2:$C$7,MATCH(D36,'Designation Defaults'!$A$2:$A$7,0)),"") -> 3 | J36: =IF(I36="",H36,I36) -> 3 | K36: NEEDS SETUP: no Initial / credit limit on file — fill in before running engine
A37: 36 | B37: Sumaya Hannan Shova | C37: SHS | D37: Lecturer | E37: =IFERROR(INDEX('Designation Defaults'!$B$2:$B$7,MATCH(D37,'Designation Defaults'!$A$2:$A$7,0)),"") -> 18 | G37: =IF(F37="",E37,F37) -> 18 | H37: =IFERROR(INDEX('Designation Defaults'!$C$2:$C$7,MATCH(D37,'Designation Defaults'!$A$2:$A$7,0)),"") -> 3 | J37: =IF(I37="",H37,I37) -> 3
A38: 37 | B38: Md. Fayzul Islam | C38: MFI | D38: Lecturer | E38: =IFERROR(INDEX('Designation Defaults'!$B$2:$B$7,MATCH(D38,'Designation Defaults'!$A$2:$A$7,0)),"") -> 18 | G38: =IF(F38="",E38,F38) -> 18 | H38: =IFERROR(INDEX('Designation Defaults'!$C$2:$C$7,MATCH(D38,'Designation Defaults'!$A$2:$A$7,0)),"") -> 3 | J38: =IF(I38="",H38,I38) -> 3
A39: 38 | B39: Md. Rakibul islam | D39: Lecturer | E39: =IFERROR(INDEX('Designation Defaults'!$B$2:$B$7,MATCH(D39,'Designation Defaults'!$A$2:$A$7,0)),"") -> 18 | G39: =IF(F39="",E39,F39) -> 18 | H39: =IFERROR(INDEX('Designation Defaults'!$C$2:$C$7,MATCH(D39,'Designation Defaults'!$A$2:$A$7,0)),"") -> 3 | J39: =IF(I39="",H39,I39) -> 3 | K39: NEEDS SETUP: no Initial / credit limit on file — fill in before running engine
A40: 39 | B40: Mst. Mazeda Noor Tasnim | D40: Lecturer | E40: =IFERROR(INDEX('Designation Defaults'!$B$2:$B$7,MATCH(D40,'Designation Defaults'!$A$2:$A$7,0)),"") -> 18 | G40: =IF(F40="",E40,F40) -> 18 | H40: =IFERROR(INDEX('Designation Defaults'!$C$2:$C$7,MATCH(D40,'Designation Defaults'!$A$2:$A$7,0)),"") -> 3 | J40: =IF(I40="",H40,I40) -> 3 | K40: NEEDS SETUP: no Initial / credit limit on file — fill in before running engine
A41: 40 | B41: Md. Adnan Sami | C41: MAS | D41: Lecturer | E41: =IFERROR(INDEX('Designation Defaults'!$B$2:$B$7,MATCH(D41,'Designation Defaults'!$A$2:$A$7,0)),"") -> 18 | G41: =IF(F41="",E41,F41) -> 18 | H41: =IFERROR(INDEX('Designation Defaults'!$C$2:$C$7,MATCH(D41,'Designation Defaults'!$A$2:$A$7,0)),"") -> 3 | J41: =IF(I41="",H41,I41) -> 3
A42: 41 | B42: Adrita Alam | C42: AAP | D42: Lecturer | E42: =IFERROR(INDEX('Designation Defaults'!$B$2:$B$7,MATCH(D42,'Designation Defaults'!$A$2:$A$7,0)),"") -> 18 | G42: =IF(F42="",E42,F42) -> 18 | H42: =IFERROR(INDEX('Designation Defaults'!$C$2:$C$7,MATCH(D42,'Designation Defaults'!$A$2:$A$7,0)),"") -> 3 | J42: =IF(I42="",H42,I42) -> 3
A43: 42 | B43: Rokaiya Tasnim | D43: Lecturer | E43: =IFERROR(INDEX('Designation Defaults'!$B$2:$B$7,MATCH(D43,'Designation Defaults'!$A$2:$A$7,0)),"") -> 18 | G43: =IF(F43="",E43,F43) -> 18 | H43: =IFERROR(INDEX('Designation Defaults'!$C$2:$C$7,MATCH(D43,'Designation Defaults'!$A$2:$A$7,0)),"") -> 3 | J43: =IF(I43="",H43,I43) -> 3 | K43: NEEDS SETUP: no Initial / credit limit on file — fill in before running engine
A44: 43 | B44: Afroza Islam | C44: AI | D44: Lecturer | E44: =IFERROR(INDEX('Designation Defaults'!$B$2:$B$7,MATCH(D44,'Designation Defaults'!$A$2:$A$7,0)),"") -> 18 | G44: =IF(F44="",E44,F44) -> 18 | H44: =IFERROR(INDEX('Designation Defaults'!$C$2:$C$7,MATCH(D44,'Designation Defaults'!$A$2:$A$7,0)),"") -> 3 | J44: =IF(I44="",H44,I44) -> 3
...
